<?xml version="1.0" ?>
<!-- =================================================================================== -->
<!-- |    This document was autogenerated by xacro from lemken_john_deere_6r.urdf.xacro | -->
<!-- |    EDITING THIS FILE BY HAND IS NOT RECOMMENDED                                 | -->
<!-- =================================================================================== -->
<robot name="kubo">
  <!-- DISCLAIMER -->
  <!-- 
        Due to the nature of xacro and to avoid macros with long param list.
        We decided to have a file with global variables for the definition of the vehicles. This global
        variables shoudln't be used in any other file that isn't: 
        * variables.urdf.xacro
        * macros.shocks.urdf.xacro
        * macros.wheels.urdf.xacro
        * desciption.urdf.xacro
        -->
  <!-- chassis_length is measured along the x axis, chassis_width
       along the y axis, and chassis_height along the z axis.
       Note: Size of chassis won't affect wheel position or function, so be
       careful about making it too big-->
  <!-- base_link -->
  <link name="base_link"/>
  <!-- Robot Footprint -->
  <link name="base_footprint"/>
  <joint name="base_joint" type="fixed">
    <parent link="base_link"/>
    <child link="base_footprint"/>
    <origin rpy="0 0 0" xyz="1.3825 0.0 0.0"/>
  </joint>
  <!-- Chassis -->
  <link name="tractor_chassis">
    <visual>
      <origin xyz="0 0 0"/>
      <geometry>
        <box size="0.5 0.3 1.0"/>
      </geometry>
      <material name="grey">
        <color rgba="0.2 0.2 0.2 1.0"/>
      </material>
    </visual>
    <!--collision>
                                <origin xyz="0 0 0" rpy=" 0 0 0" />
                                <geometry>
                                        <box size="${chassis_length} ${chassis_width} ${chassis_height}" />
                                </geometry>
                        </collision-->
    <inertial>
      <origin rpy=" 0 0 0" xyz="0 0 0"/>
      <mass value="500"/>
      <inertia ixx="45.416666666666664" ixy="0" ixz="0" iyy="52.083333333333336" iyz="0" izz="14.166666666666664"/>
    </inertial>
  </link>
  <joint name="base_link_to_chassis" type="fixed">
    <parent link="base_link"/>
    <child link="tractor_chassis"/>
    <origin rpy="0 0 0" xyz="0 0 1.0"/>
  </joint>
  <!-- std_vehicle_frame -->
  <link name="std_vehicle_frame"/>
  <joint name="std_vehicle_frame_joint" type="fixed">
    <parent link="tractor_chassis"/>
    <child link="std_vehicle_frame"/>
    <origin rpy="0 0 0" xyz="1.3825 0.0 -0.05500000000000005"/>
  </joint>
  <!-- cover -->
  <link name="cover">
    <visual>
      <origin rpy="0 0 1.57079633" xyz="1.22 0.0 -0.945"/>
      <geometry>
        <mesh filename="file:///home/ros/ws/common_ws/install/vehicle_description/share/vehicle_description/models/john_deere_6r/meshes/JD6M.dae"/>
      </geometry>
      <material name="grey">
        <color rgba="0.2 0.2 0.2 1.0"/>
      </material>
    </visual>
    <collision>
      <origin rpy="0 0 1.57079633" xyz="1.22 0.0 -0.945"/>
      <geometry>
        <mesh filename="file:///home/ros/ws/common_ws/install/vehicle_description/share/vehicle_description/models/john_deere_6r/meshes/JD6M.dae"/>
      </geometry>
    </collision>
    <inertial>
      <origin xyz="0 0 0"/>
      <mass value="1"/>
      <inertia ixx="0.006666666666666668" ixy="0" ixz="0" iyy="0.5241666666666667" iyz="0" izz="0.5241666666666667"/>
    </inertial>
  </link>
  <joint name="cover_to_chassis" type="fixed">
    <parent link="tractor_chassis"/>
    <child link="cover"/>
    <origin rpy="0 0 0" xyz="0 0 0"/>
  </joint>
  <!-- frontaxle -->
  <link name="frontaxle">
    <visual>
      <origin xyz="0 0 0"/>
      <geometry>
        <box size="0.1 1.4 0.15"/>
      </geometry>
      <material name="grey">
        <color rgba="0.2 0.2 0.2 1.0"/>
      </material>
    </visual>
    <!--collision>
                                <origin xyz="0 0 0" />
                                <geometry>
                                        <box size="0.1 1.4 0.15" />
                                </geometry>
                        </collision-->
    <inertial>
      <origin xyz="0 0 0"/>
      <mass value="0.0001"/>
      <inertia ixx="1.652083333333333e-05" ixy="0" ixz="0" iyy="2.7083333333333337e-07" iyz="0" izz="1.6416666666666665e-05"/>
    </inertial>
  </link>
  <joint name="frontaxle_to_chassis" type="fixed">
    <parent link="tractor_chassis"/>
    <child link="frontaxle"/>
    <origin rpy="0 0 0" xyz="2.765 0 0"/>
    <axis xyz="1 0 0"/>
    <limit effort="0" lower="-0.785398163" upper="0.785398163" velocity="10"/>
  </joint>
  <joint name="left_front_shock" type="fixed">
    <parent link="frontaxle"/>
    <child link="left_steering_link"/>
    <origin xyz="0                    1.05                    -0.2865"/>
    <axis xyz="0 0 -1"/>
    <!--limit lower="${-wheel_travel / 2}" upper="${wheel_travel / 2}" effort="${shock_eff_limit}" velocity="${shock_vel_limit}"/-->
  </joint>
  <!--transmission name="${lr_prefix}_${fr_prefix}_shock_trans">
      <type>transmission_interface/SimpleTransmission</type>
      <joint name="${lr_prefix}_${fr_prefix}_shock">
        <hardwareInterface>hardware_interface/EffortJointInterface</hardwareInterface>
      </joint>
      <actuator name="${lr_prefix}_${fr_prefix}_shock_act"-->
  <!-- This hardwareInterface element exists for compatibility
             with ROS Hydro. -->
  <!--hardwareInterface>hardware_interface/EffortJointInterface</hardwareInterface>
        <mechanicalReduction>1</mechanicalReduction>
      </actuator>
    </transmission-->
  <link name="left_steering_link">
    <!--xacro:null_inertial/-->
    <inertial>
      <mass value="0.001"/>
      <origin rpy=" 0 0 0" xyz="0 0 0"/>
      <inertia ixx="1e-2" ixy="0" ixz="0" iyy="1e-3" iyz="0" izz="1e-3"/>
    </inertial>
  </link>
  <joint name="left_steering_joint" type="revolute">
    <parent link="left_steering_link"/>
    <child link="left_front_axle_carrier"/>
    <axis xyz="0 0 1"/>
    <limit effort="5649" lower="-0.785398163" upper="0.785398163" velocity="4553"/>
  </joint>
  <transmission name="left_steering_trans">
    <type>transmission_interface/SimpleTransmission</type>
    <joint name="left_steering_joint">
      <hardwareInterface>hardware_interface/EffortJointInterface</hardwareInterface>
    </joint>
    <actuator name="left_steering_act">
      <!-- This hardwareInterface element exists for compatibility
             with ROS Hydro. -->
      <hardwareInterface>hardware_interface/EffortJointInterface</hardwareInterface>
      <mechanicalReduction>1</mechanicalReduction>
    </actuator>
  </transmission>
  <link name="left_front_axle_carrier">
    <inertial>
      <mass value="0.0005"/>
      <origin rpy=" 0 0 0" xyz="0 0 0"/>
      <inertia ixx="0.001" ixy="0" ixz="0" iyy="0.001" iyz="0" izz="0.001"/>
    </inertial>
  </link>
  <!-- The left and right axles have the same axis so that identical
         rotation values cause the wheels to rotate in the same direction. -->
  <joint name="left_front_axle" type="continuous">
    <parent link="left_front_axle_carrier"/>
    <child link="left_front_wheel"/>
    <origin rpy="1.57079633 0 0"/>
    <axis xyz="0 0 -1"/>
    <limit effort="512766" velocity="100"/>
  </joint>
  <transmission name="left_front_axle_trans">
    <type>transmission_interface/SimpleTransmission</type>
    <joint name="left_front_axle">
      <hardwareInterface>hardware_interface/EffortJointInterface</hardwareInterface>
    </joint>
    <actuator name="left_front_axle_act">
      <!-- This hardwareInterface element exists for compatibility
             with ROS Hydro. -->
      <hardwareInterface>hardware_interface/EffortJointInterface</hardwareInterface>
      <mechanicalReduction>1</mechanicalReduction>
    </actuator>
  </transmission>
  <link name="left_front_wheel">
    <visual>
      <origin rpy="1.57079633 0 0" xyz="0 -0.0 0"/>
      <geometry>
        <mesh filename="file:///home/ros/ws/common_ws/install/vehicle_description/share/vehicle_description/models/john_deere_6r/meshes/front_wheel.dae" scale="1.9819444444444445 2.938888888888889 1.9819444444444445"/>
      </geometry>
    </visual>
    <collision>
      <origin xyz="0 -0.0 0"/>
      <geometry>
        <cylinder length="0.1" radius="0.7135"/>
      </geometry>
      <surface>
        <friction>
          <ode>
            <mu>1</mu>
            <mu2>0.25</mu2>
            <slip1>0.00001</slip1>
            <slip2>0.00001</slip2>
          </ode>
        </friction>
        <contact>
          <ode>
            <soft_cfm>0</soft_cfm>
            <soft_erp>0.2</soft_erp>
            <kp>1e+10</kp>
            <kd>1</kd>
            <min_depth>0.01</min_depth>
          </ode>
        </contact>
      </surface>
    </collision>
    <inertial>
      <mass value="10"/>
      <inertia ixx="1.3060389583333334" ixy="0" ixz="0" iyy="1.3060389583333334" iyz="0" izz="2.5954112500000006"/>
    </inertial>
  </link>
  <joint name="right_front_shock" type="fixed">
    <parent link="frontaxle"/>
    <child link="right_steering_link"/>
    <origin xyz="0                    -1.05                    -0.2865"/>
    <axis xyz="0 0 -1"/>
    <!--limit lower="${-wheel_travel / 2}" upper="${wheel_travel / 2}" effort="${shock_eff_limit}" velocity="${shock_vel_limit}"/-->
  </joint>
  <!--transmission name="${lr_prefix}_${fr_prefix}_shock_trans">
      <type>transmission_interface/SimpleTransmission</type>
      <joint name="${lr_prefix}_${fr_prefix}_shock">
        <hardwareInterface>hardware_interface/EffortJointInterface</hardwareInterface>
      </joint>
      <actuator name="${lr_prefix}_${fr_prefix}_shock_act"-->
  <!-- This hardwareInterface element exists for compatibility
             with ROS Hydro. -->
  <!--hardwareInterface>hardware_interface/EffortJointInterface</hardwareInterface>
        <mechanicalReduction>1</mechanicalReduction>
      </actuator>
    </transmission-->
  <link name="right_steering_link">
    <!--xacro:null_inertial/-->
    <inertial>
      <mass value="0.001"/>
      <origin rpy=" 0 0 0" xyz="0 0 0"/>
      <inertia ixx="1e-2" ixy="0" ixz="0" iyy="1e-3" iyz="0" izz="1e-3"/>
    </inertial>
  </link>
  <joint name="right_steering_joint" type="revolute">
    <parent link="right_steering_link"/>
    <child link="right_front_axle_carrier"/>
    <axis xyz="0 0 1"/>
    <limit effort="5649" lower="-0.785398163" upper="0.785398163" velocity="4553"/>
  </joint>
  <transmission name="right_steering_trans">
    <type>transmission_interface/SimpleTransmission</type>
    <joint name="right_steering_joint">
      <hardwareInterface>hardware_interface/EffortJointInterface</hardwareInterface>
    </joint>
    <actuator name="right_steering_act">
      <!-- This hardwareInterface element exists for compatibility
             with ROS Hydro. -->
      <hardwareInterface>hardware_interface/EffortJointInterface</hardwareInterface>
      <mechanicalReduction>1</mechanicalReduction>
    </actuator>
  </transmission>
  <link name="right_front_axle_carrier">
    <inertial>
      <mass value="0.0005"/>
      <origin rpy=" 0 0 0" xyz="0 0 0"/>
      <inertia ixx="0.001" ixy="0" ixz="0" iyy="0.001" iyz="0" izz="0.001"/>
    </inertial>
  </link>
  <!-- The left and right axles have the same axis so that identical
         rotation values cause the wheels to rotate in the same direction. -->
  <joint name="right_front_axle" type="continuous">
    <parent link="right_front_axle_carrier"/>
    <child link="right_front_wheel"/>
    <origin rpy="1.57079633 0 0"/>
    <axis xyz="0 0 -1"/>
    <limit effort="512766" velocity="100"/>
  </joint>
  <transmission name="right_front_axle_trans">
    <type>transmission_interface/SimpleTransmission</type>
    <joint name="right_front_axle">
      <hardwareInterface>hardware_interface/EffortJointInterface</hardwareInterface>
    </joint>
    <actuator name="right_front_axle_act">
      <!-- This hardwareInterface element exists for compatibility
             with ROS Hydro. -->
      <hardwareInterface>hardware_interface/EffortJointInterface</hardwareInterface>
      <mechanicalReduction>1</mechanicalReduction>
    </actuator>
  </transmission>
  <link name="right_front_wheel">
    <visual>
      <origin rpy="-1.57079633 0 0" xyz="0 0.0 0"/>
      <geometry>
        <mesh filename="file:///home/ros/ws/common_ws/install/vehicle_description/share/vehicle_description/models/john_deere_6r/meshes/front_wheel.dae" scale="1.9819444444444445 2.938888888888889 1.9819444444444445"/>
      </geometry>
    </visual>
    <collision>
      <origin xyz="0 0.0 0"/>
      <geometry>
        <cylinder length="0.1" radius="0.7135"/>
      </geometry>
      <surface>
        <friction>
          <ode>
            <mu>1</mu>
            <mu2>0.25</mu2>
            <slip1>0.00001</slip1>
            <slip2>0.00001</slip2>
          </ode>
        </friction>
        <contact>
          <ode>
            <soft_cfm>0</soft_cfm>
            <soft_erp>0.2</soft_erp>
            <kp>1e+10</kp>
            <kd>1</kd>
            <min_depth>0.01</min_depth>
          </ode>
        </contact>
      </surface>
    </collision>
    <inertial>
      <mass value="10"/>
      <inertia ixx="1.3060389583333334" ixy="0" ixz="0" iyy="1.3060389583333334" iyz="0" izz="2.5954112500000006"/>
    </inertial>
  </link>
  <joint name="left_rear_shock" type="fixed">
    <parent link="tractor_chassis"/>
    <child link="left_rear_axle_carrier"/>
    <origin xyz="0.0                    0.925                    -0.05500000000000005"/>
    <axis xyz="0 0 -1"/>
    <!--limit lower="${-wheel_travel / 2}" upper="${wheel_travel / 2}" effort="${shock_eff_limit}" velocity="${shock_vel_limit}"/-->
  </joint>
  <!--transmission name="${lr_prefix}_${fr_prefix}_shock_trans">
      <type>transmission_interface/SimpleTransmission</type>
      <joint name="${lr_prefix}_${fr_prefix}_shock">
        <hardwareInterface>hardware_interface/EffortJointInterface</hardwareInterface>
      </joint>
      <actuator name="${lr_prefix}_${fr_prefix}_shock_act"-->
  <!-- This hardwareInterface element exists for compatibility
             with ROS Hydro. -->
  <!--hardwareInterface>hardware_interface/EffortJointInterface</hardwareInterface>
        <mechanicalReduction>1</mechanicalReduction>
      </actuator>
    </transmission-->
  <link name="left_rear_axle_carrier">
    <!--xacro:null_inertial/-->
    <inertial>
      <mass value="0.001"/>
      <origin rpy=" 0 0 0" xyz="0 0 0"/>
      <inertia ixx="1e-2" ixy="0" ixz="0" iyy="1e-3" iyz="0" izz="1e-3"/>
    </inertial>
  </link>
  <!-- The left and right axles have the same axis so that identical
         rotation values cause the wheels to rotate in the same direction. -->
  <joint name="left_rear_axle" type="continuous">
    <parent link="left_rear_axle_carrier"/>
    <child link="left_rear_wheel"/>
    <origin rpy="1.57079633 0 0"/>
    <axis xyz="0 0 -1"/>
    <limit effort="512766" velocity="100"/>
  </joint>
  <transmission name="left_rear_axle_trans">
    <type>transmission_interface/SimpleTransmission</type>
    <joint name="left_rear_axle">
      <hardwareInterface>hardware_interface/EffortJointInterface</hardwareInterface>
    </joint>
    <actuator name="left_rear_axle_act">
      <!-- This hardwareInterface element exists for compatibility
             with ROS Hydro. -->
      <hardwareInterface>hardware_interface/EffortJointInterface</hardwareInterface>
      <mechanicalReduction>1</mechanicalReduction>
    </actuator>
  </transmission>
  <link name="left_rear_wheel">
    <visual>
      <origin rpy="1.57079633 0 0" xyz="0 -0.0 0"/>
      <geometry>
        <mesh filename="file:///home/ros/ws/common_ws/install/vehicle_description/share/vehicle_description/models/john_deere_6r/meshes/rear_wheel.dae" scale="2.5 3.588888888888889 2.5"/>
      </geometry>
    </visual>
    <collision>
      <origin xyz="0  -0.0 0"/>
      <geometry>
        <cylinder length="0.1" radius="0.945"/>
        <surface>
          <friction>
            <ode>
              <mu>1</mu>
              <mu2>0.25</mu2>
              <slip1>0.00001</slip1>
              <slip2>0.00001</slip2>
            </ode>
          </friction>
          <contact>
            <ode>
              <soft_cfm>0</soft_cfm>
              <soft_erp>0.2</soft_erp>
              <kp>1e+10</kp>
              <kd>1</kd>
              <min_depth>0.01</min_depth>
            </ode>
          </contact>
        </surface>
      </geometry>
    </collision>
    <inertial>
      <mass value="10.0"/>
      <inertia ixx="2.265895833333333" ixy="0" ixz="0" iyy="2.265895833333333" iyz="0" izz="4.515124999999999"/>
    </inertial>
  </link>
  <joint name="right_rear_shock" type="fixed">
    <parent link="tractor_chassis"/>
    <child link="right_rear_axle_carrier"/>
    <origin xyz="0.0                    -0.925                    -0.05500000000000005"/>
    <axis xyz="0 0 -1"/>
    <!--limit lower="${-wheel_travel / 2}" upper="${wheel_travel / 2}" effort="${shock_eff_limit}" velocity="${shock_vel_limit}"/-->
  </joint>
  <!--transmission name="${lr_prefix}_${fr_prefix}_shock_trans">
      <type>transmission_interface/SimpleTransmission</type>
      <joint name="${lr_prefix}_${fr_prefix}_shock">
        <hardwareInterface>hardware_interface/EffortJointInterface</hardwareInterface>
      </joint>
      <actuator name="${lr_prefix}_${fr_prefix}_shock_act"-->
  <!-- This hardwareInterface element exists for compatibility
             with ROS Hydro. -->
  <!--hardwareInterface>hardware_interface/EffortJointInterface</hardwareInterface>
        <mechanicalReduction>1</mechanicalReduction>
      </actuator>
    </transmission-->
  <link name="right_rear_axle_carrier">
    <!--xacro:null_inertial/-->
    <inertial>
      <mass value="0.001"/>
      <origin rpy=" 0 0 0" xyz="0 0 0"/>
      <inertia ixx="1e-2" ixy="0" ixz="0" iyy="1e-3" iyz="0" izz="1e-3"/>
    </inertial>
  </link>
  <!-- The left and right axles have the same axis so that identical
         rotation values cause the wheels to rotate in the same direction. -->
  <joint name="right_rear_axle" type="continuous">
    <parent link="right_rear_axle_carrier"/>
    <child link="right_rear_wheel"/>
    <origin rpy="1.57079633 0 0"/>
    <axis xyz="0 0 -1"/>
    <limit effort="512766" velocity="100"/>
  </joint>
  <transmission name="right_rear_axle_trans">
    <type>transmission_interface/SimpleTransmission</type>
    <joint name="right_rear_axle">
      <hardwareInterface>hardware_interface/EffortJointInterface</hardwareInterface>
    </joint>
    <actuator name="right_rear_axle_act">
      <!-- This hardwareInterface element exists for compatibility
             with ROS Hydro. -->
      <hardwareInterface>hardware_interface/EffortJointInterface</hardwareInterface>
      <mechanicalReduction>1</mechanicalReduction>
    </actuator>
  </transmission>
  <link name="right_rear_wheel">
    <visual>
      <origin rpy="-1.57079633 0 0" xyz="0 0.0 0"/>
      <geometry>
        <mesh filename="file:///home/ros/ws/common_ws/install/vehicle_description/share/vehicle_description/models/john_deere_6r/meshes/rear_wheel.dae" scale="2.5 3.588888888888889 2.5"/>
      </geometry>
    </visual>
    <collision>
      <origin xyz="0  0.0 0"/>
      <geometry>
        <cylinder length="0.1" radius="0.945"/>
        <surface>
          <friction>
            <ode>
              <mu>1</mu>
              <mu2>0.25</mu2>
              <slip1>0.00001</slip1>
              <slip2>0.00001</slip2>
            </ode>
          </friction>
          <contact>
            <ode>
              <soft_cfm>0</soft_cfm>
              <soft_erp>0.2</soft_erp>
              <kp>1e+10</kp>
              <kd>1</kd>
              <min_depth>0.01</min_depth>
            </ode>
          </contact>
        </surface>
      </geometry>
    </collision>
    <inertial>
      <mass value="10.0"/>
      <inertia ixx="2.265895833333333" ixy="0" ixz="0" iyy="2.265895833333333" iyz="0" izz="4.515124999999999"/>
    </inertial>
  </link>
  <!-- Base Link -->
  <joint name="hitch_rear_base_joint" type="fixed">
    <origin rpy="0 0 0" xyz="-0.05 0 -0.28"/>
    <parent link="tractor_chassis"/>
    <child link="hitch_rear_base_link"/>
  </joint>
  <link name="hitch_rear_base_link">
    <collision>
      <origin rpy="0 0 0" xyz="0 0 0.2"/>
      <geometry>
        <box size="0.05 0.9 0.4"/>
      </geometry>
    </collision>
    <visual>
      <origin rpy="0 0 0" xyz="0 0 0.2"/>
      <geometry>
        <box size="0.05 0.9 0.4"/>
      </geometry>
      <material name="black">
        <color rgba="0.0 0.0 0.0 1.0"/>
      </material>
    </visual>
    <inertial>
      <origin rpy="0 0 0" xyz="0 0 0.2"/>
      <mass value="1"/>
      <inertia ixx="0.013541666666666669" ixy="0" ixz="0" iyy="0.08083333333333334" iyz="0" izz="0.06770833333333333"/>
    </inertial>
  </link>
  <!-- Upper linkage point -->
  <joint name="hitch_rear_upper_linkage_point_to_base" type="revolute">
    <parent link="hitch_rear_base_link"/>
    <child link="hitch_rear_upper_linkage_point"/>
    <origin rpy="0 0 0" xyz="-0.45 0 0.4"/>
    <axis xyz="0 1 0"/>
    <dynamics damping="0.7"/>
    <limit effort="100" lower="-1.57" upper="1.57" velocity="10"/>
  </joint>
  <link name="hitch_rear_upper_linkage_point">
    <collision>
      <origin rpy="0 0 0" xyz="0 0 0"/>
      <geometry>
        <box size="0.05 0.1 0.05"/>
      </geometry>
    </collision>
    <visual>
      <origin rpy="0 0 0" xyz="0 0 0"/>
      <geometry>
        <box size="0.05 0.1 0.05"/>
      </geometry>
      <material name="white">
        <color rgba="1.0 1.0 1.0 1.0"/>
      </material>
    </visual>
    <inertial>
      <origin rpy="0 0 0" xyz="0 0 0"/>
      <mass value="1"/>
      <inertia ixx="0.00041666666666666675" ixy="0" ixz="0" iyy="0.0010416666666666669" iyz="0" izz="0.0010416666666666669"/>
    </inertial>
  </link>
  <!-- Upper linkage -->
  <joint name="hitch_rear_upper_linkage_to_upper_linkage_point" type="fixed">
    <parent link="hitch_rear_upper_linkage_point"/>
    <child link="hitch_rear_upper_linkage"/>
    <origin rpy="0 0 0" xyz="-0.8600000000000001 0 0"/>
    <axis xyz="0 1 0"/>
  </joint>
  <link name="hitch_rear_upper_linkage">
    <collision>
      <origin rpy="0 0 0" xyz="0.405 0 0"/>
      <geometry>
        <box size="0.81 0.05 0.05"/>
      </geometry>
    </collision>
    <visual>
      <origin rpy="0 0 0" xyz="0.405 0 0"/>
      <geometry>
        <box size="0.81 0.05 0.05"/>
      </geometry>
      <material name="white">
        <color rgba="1.0 1.0 1.0 1.0"/>
      </material>
    </visual>
    <inertial>
      <origin rpy="0 0 0" xyz="0 0 0.405"/>
      <mass value="1"/>
      <inertia ixx="0.05488333333333334" ixy="0" ixz="0" iyy="0.00041666666666666675" iyz="0" izz="0.05488333333333334"/>
    </inertial>
  </link>
  <!-- =========== -->
  <!-- Lower linkage point -->
  <joint name="hitch_rear_lower_linkage_point_to_base" type="revolute">
    <parent link="hitch_rear_base_link"/>
    <child link="hitch_rear_lower_linkage_point"/>
    <origin rpy="0 0 0" xyz="-0.1 0 0"/>
    <axis xyz="0 1 0"/>
    <dynamics damping="0.7"/>
    <limit effort="1000" lower="-0.26" upper="0.5" velocity="10"/>
  </joint>
  <link name="hitch_rear_lower_linkage_point">
    <collision>
      <origin rpy="0 0 0" xyz="0 0 0"/>
      <geometry>
        <box size="0.05 0.9 0.05"/>
      </geometry>
    </collision>
    <visual>
      <origin rpy="0 0 0" xyz="0 0 0"/>
      <geometry>
        <box size="0.05 0.9 0.05"/>
      </geometry>
      <material name="white">
        <color rgba="1.0 1.0 1.0 1.0"/>
      </material>
    </visual>
    <inertial>
      <origin rpy="0 0 0" xyz="0 0 0"/>
      <mass value="1"/>
      <inertia ixx="0.00041666666666666675" ixy="0" ixz="0" iyy="0.06770833333333333" iyz="0" izz="0.06770833333333333"/>
    </inertial>
  </link>
  <!-- Lower linkage -->
  <joint name="hitch_rear_lower_linkage_to_lower_linkage_point" type="fixed">
    <parent link="hitch_rear_lower_linkage_point"/>
    <child link="hitch_rear_lower_linkage"/>
    <origin rpy="0 0 0" xyz="-1.135 0 0"/>
    <axis xyz="0 0 0"/>
  </joint>
  <link name="hitch_rear_lower_linkage">
    <collision>
      <origin rpy="0 0 0" xyz="0.5425 0 0"/>
      <geometry>
        <box size="1.085 0.9 0.05"/>
      </geometry>
    </collision>
    <visual>
      <origin rpy="0 0 0" xyz="0.5425 0 0"/>
      <geometry>
        <box size="1.085 0.9 0.05"/>
      </geometry>
      <material name="white">
        <color rgba="1.0 1.0 1.0 1.0"/>
      </material>
    </visual>
    <inertial>
      <origin rpy="0 0 0" xyz="0.5425 0 0"/>
      <mass value="1"/>
      <inertia ixx="0.09831041666666666" ixy="0" ixz="0" iyy="0.06770833333333333" iyz="0" izz="0.16560208333333334"/>
    </inertial>
  </link>
  <!-- Lower hitch point -->
  <joint name="hitch_rear_lower_hitch_point_to_lower_linkage" type="revolute">
    <parent link="hitch_rear_lower_linkage"/>
    <child link="hitch_rear_lower_hitch_point"/>
    <origin rpy="0 0 0" xyz="-0.1 0 0"/>
    <axis xyz="0 1 0"/>
    <dynamics damping="0.7"/>
    <limit effort="1000" lower="-1.57" upper="1.57" velocity="10"/>
  </joint>
  <link name="hitch_rear_lower_hitch_point">
    <collision>
      <origin rpy="0 0 0" xyz="0 0 0"/>
      <geometry>
        <box size="0.05 0.9 0.05"/>
      </geometry>
    </collision>
    <visual>
      <origin rpy="0 0 0" xyz="0 0 0"/>
      <geometry>
        <box size="0.05 0.9 0.05"/>
      </geometry>
      <material name="white">
        <color rgba="1.0 1.0 1.0 1.0"/>
      </material>
    </visual>
    <inertial>
      <origin rpy="0 0 0" xyz="0 0 0"/>
      <mass value="1"/>
      <inertia ixx="0.00041666666666666675" ixy="0" ixz="0" iyy="0.06770833333333333" iyz="0" izz="0.06770833333333333"/>
    </inertial>
  </link>
  <!-- Lower linkage front -->
  <link name="lower_linkage_front">
    <visual>
      <origin xyz="0.45 0 0"/>
      <geometry>
        <box size="0.9 0.9 0.05"/>
      </geometry>
      <material name="grey">
        <color rgba="0.2 0.2 0.2 1.0"/>
      </material>
    </visual>
    <collision>
      <origin xyz="0.45 0 0"/>
      <geometry>
        <box size="0.9 0.9 0.05"/>
      </geometry>
    </collision>
    <inertial>
      <origin xyz="0.45 0 0"/>
      <mass value="1e-05"/>
      <inertia ixx="6.770833333333335e-07" ixy="0" ixz="0" iyy="6.770833333333335e-07" iyz="0" izz="1.35e-06"/>
    </inertial>
  </link>
  <joint name="lower_linkage_front_to_chassis" type="fixed">
    <parent link="tractor_chassis"/>
    <child link="lower_linkage_front"/>
    <limit effort="100" lower="-0.5" upper="0.26" velocity="1"/>
    <origin rpy="0 0 0" xyz="3.115 0 -0.35"/>
    <axis xyz="0 1 0"/>
  </joint>
  <!-- Lower hitch point front -->
  <link name="lower_hitch_point_front">
    <visual>
      <origin rpy="1.57079633 0 0" xyz="0 0 0"/>
      <geometry>
        <cylinder length="1.1" radius="0.02"/>
      </geometry>
      <material name="grey">
        <color rgba="0.2 0.2 0.2 1.0"/>
      </material>
    </visual>
    <collision>
      <origin rpy="1.57079633 0 0" xyz="0 0 0"/>
      <geometry>
        <cylinder length="1.1" radius="0.02"/>
      </geometry>
    </collision>
    <inertial>
      <origin xyz="0 0 0"/>
      <mass value="0.0001"/>
      <inertia ixx="1.0086666666666668e-05" ixy="0" ixz="0" iyy="6.666666666666667e-09" iyz="0" izz="1.0086666666666668e-05"/>
    </inertial>
  </link>
  <joint name="lower_hitch_point_front_to_lower_linkage_front" type="fixed">
    <parent link="lower_linkage_front"/>
    <child link="lower_hitch_point_front"/>
    <origin rpy="0 0 0" xyz="0.9 0 0"/>
    <axis xyz="0 1 0"/>
  </joint>
  <!-- Upper linkage front -->
  <link name="upper_linkage_front">
    <visual>
      <origin xyz="0.35 0 0"/>
      <geometry>
        <box size="0.7 0.05 0.05"/>
      </geometry>
      <material name="grey">
        <color rgba="0.2 0.2 0.2 1.0"/>
      </material>
    </visual>
    <collision>
      <origin xyz="0.35 0 0"/>
      <geometry>
        <box size="0.7 0.05 0.05"/>
      </geometry>
    </collision>
    <inertial>
      <origin xyz="0.35 0 0"/>
      <mass value="1e-05"/>
      <inertia ixx="4.1666666666666676e-09" ixy="0" ixz="0" iyy="4.104166666666666e-07" iyz="0" izz="4.104166666666666e-07"/>
    </inertial>
  </link>
  <joint name="upper_linkage_front_to_chassis" type="fixed">
    <parent link="tractor_chassis"/>
    <child link="upper_linkage_front"/>
    <limit effort="100" lower="-0.26" upper="0.50" velocity="1"/>
    <origin rpy="0 0.05 0" xyz="3.265 0 0.2"/>
    <axis xyz="0 1 0"/>
  </joint>
  <!-- Roof base measurement point -->
  <link name="roof_base">
    <visual name="roof_base_visual">
      <origin rpy=" 0 0 0" xyz="0 0 0"/>
      <geometry>
        <box size="0.01 0.01 0.01"/>
      </geometry>
    </visual>
    <collision name="roof_base_collision">
      <origin rpy=" 0 0 0" xyz="0 0 0"/>
      <geometry>
        <box size="0.01 0.01 0.01"/>
      </geometry>
    </collision>
    <inertial>
      <mass value="0.01"/>
      <origin rpy=" 0 0 0" xyz="0 0 0"/>
      <inertia ixx="1e-6" ixy="0" ixz="0" iyy="1e-6" iyz="0" izz="1e-6"/>
    </inertial>
  </link>
  <joint name="roof_base_joint" type="fixed">
    <origin rpy="0 0 0" xyz="0.29 0 2.0"/>
    <parent link="tractor_chassis"/>
    <child link="roof_base"/>
  </joint>
  <!-- Front top mount -->
  <link name="front_top_mount">
    <visual name="front_top_mount_visual">
      <origin rpy=" 0 0 0" xyz="0 0 0"/>
      <geometry>
        <box size="0.1 0.1 0.005"/>
      </geometry>
    </visual>
    <collision name="front_top_mount_collision">
      <origin rpy=" 0 0 0" xyz="0 0 0"/>
      <geometry>
        <box size="0.1 0.1 0.005"/>
      </geometry>
    </collision>
    <inertial>
      <mass value="0.1"/>
      <origin rpy=" 0 0 0" xyz="0 0 0"/>
      <inertia ixx="1e-6" ixy="0" ixz="0" iyy="1e-6" iyz="0" izz="1e-6"/>
    </inertial>
  </link>
  <joint name="front_top_mount_joint" type="fixed">
    <origin rpy="0 0.7 0" xyz="1.65 0 0.1"/>
    <parent link="roof_base"/>
    <child link="front_top_mount"/>
  </joint>
  <!-- Ark cam mini bracket -->
  <link name="ark_cam_mini_bracket_front">
    <visual name="ark_cam_mini_bracket_front_visual">
      <origin rpy="1.57079 0 1.57079" xyz="0 0 0"/>
      <geometry>
        <mesh filename="file:///home/ros/ws/common_ws/install/sensor_description/share/sensor_description/models/arkvision_arkcam_mini/meshes/ark_cam_basic_bracket_red.dae" scale="0.001 0.001 0.001"/>
      </geometry>
    </visual>
    <collision name="ark_cam_mini_bracket_front_collision">
      <origin rpy=" 0 0 0" xyz="0 0 0"/>
      <geometry>
        <box size="0.05 0.05 0.05"/>
      </geometry>
    </collision>
    <inertial>
      <mass value="0.1"/>
      <origin rpy=" 0 0 0" xyz="0 0 0"/>
      <inertia ixx="1e-6" ixy="0" ixz="0" iyy="1e-6" iyz="0" izz="1e-6"/>
    </inertial>
  </link>
  <joint name="ark_cam_mini_bracket_front_joint" type="fixed">
    <origin rpy="0 0 0" xyz="-0.02 0 -0.05"/>
    <parent link="front_top_mount"/>
    <child link="ark_cam_mini_bracket_front"/>
  </joint>
  <!-- Rear top mount -->
  <link name="rear_top_mount">
    <visual name="rear_top_mount_visual">
      <origin rpy=" 0 0 0" xyz="0 0 0"/>
      <geometry>
        <box size="0.1 0.1 0.005"/>
      </geometry>
    </visual>
    <collision name="rear_top_mount_collision">
      <origin rpy=" 0 0 0" xyz="0 0 0"/>
      <geometry>
        <box size="0.1 0.1 0.005"/>
      </geometry>
    </collision>
    <inertial>
      <mass value="0.1"/>
      <origin rpy=" 0 0 0" xyz="0 0 0"/>
      <inertia ixx="1e-6" ixy="0" ixz="0" iyy="1e-6" iyz="0" izz="1e-6"/>
    </inertial>
  </link>
  <joint name="rear_top_mount_joint" type="fixed">
    <origin rpy="0.0 0.74 3.141592" xyz="-0.7 0 0.1"/>
    <parent link="roof_base"/>
    <child link="rear_top_mount"/>
  </joint>
  <!-- Ark cam mini bracket -->
  <link name="ark_cam_mini_bracket_rear">
    <visual name="ark_cam_mini_bracket_rear_visual">
      <origin rpy="1.57079 0 1.57079" xyz="0 0 0"/>
      <geometry>
        <mesh filename="file:///home/ros/ws/common_ws/install/sensor_description/share/sensor_description/models/arkvision_arkcam_mini/meshes/ark_cam_basic_bracket_red.dae" scale="0.001 0.001 0.001"/>
      </geometry>
    </visual>
    <collision name="ark_cam_mini_bracket_rear_collision">
      <origin rpy=" 0 0 0" xyz="0 0 0"/>
      <geometry>
        <box size="0.05 0.05 0.05"/>
      </geometry>
    </collision>
    <inertial>
      <mass value="0.1"/>
      <origin rpy=" 0 0 0" xyz="0 0 0"/>
      <inertia ixx="1e-6" ixy="0" ixz="0" iyy="1e-6" iyz="0" izz="1e-6"/>
    </inertial>
  </link>
  <joint name="ark_cam_mini_bracket_rear_joint" type="fixed">
    <origin rpy="0 0 0" xyz="-0.02 0 -0.05"/>
    <parent link="rear_top_mount"/>
    <child link="ark_cam_mini_bracket_rear"/>
  </joint>
  <!-- Sensor coordinate frame pointing opposite direction of connector at the bottom of the sensor -->
  <link name="nominal_tractor_lidar_front">
    <inertial>
      <mass value="0.00002"/>
      <origin xyz="0 0 0.03585"/>
      <inertia ixx="2.1880950000000003e-08" ixy="0" ixz="0" iyy="2.1880950000000003e-08" iyz="0" izz="2.66256e-08"/>
    </inertial>
    <visual>
      <origin rpy="1.5708 0 -1.5708" xyz="0 0 0"/>
      <geometry>
        <mesh filename="file:///home/ros/ws/common_ws/install/sensor_description/share/sensor_description/models/ouster_OS0-128/meshes/OS0.dae"/>
      </geometry>
    </visual>
    <collision>
      <origin rpy="0 0 0" xyz="0 0 0.03585"/>
      <geometry>
        <cylinder length="0.0717" radius="0.0516"/>
      </geometry>
    </collision>
  </link>
  <joint name="nominal_tractor_lidar_front_joint" type="fixed">
    <origin rpy="0 0 3.141592653589793" xyz="0 0 0.0025"/>
    <parent link="front_top_mount"/>
    <child link="nominal_tractor_lidar_front"/>
  </joint>
  <link name="tractor_lidar_front/laser"/>
  <joint name="tractor_lidar_front_laser" type="fixed">
    <origin rpy="0.0 0.0 3.14" xyz="0 0 36.180e-3"/>
    <parent link="tractor_lidar_front"/>
    <child link="tractor_lidar_front/laser"/>
  </joint>
  <link name="tractor_lidar_front/imu"/>
  <joint name="tractor_lidar_front_imu" type="fixed">
    <origin rpy="0.0 0.0 0.0" xyz="6.253e-3 -11.775e-3 7.645e-3"/>
    <parent link="tractor_lidar_front"/>
    <child link="tractor_lidar_front/imu"/>
  </joint>
  <link name="tractor_lidar_front">
    <inertial>
      <mass value="0.0005"/>
      <origin rpy=" 0 0 0" xyz="0 0 0"/>
      <inertia ixx="0.001" ixy="0" ixz="0" iyy="0.001" iyz="0" izz="0.001"/>
    </inertial>
  </link>
  <joint name="nominal_tractor_lidar_front_tractor_lidar_front_joint" type="fixed">
    <parent link="nominal_tractor_lidar_front"/>
    <child link="tractor_lidar_front"/>
    <origin rpy="-0.03 0 -1.5708" xyz="0 0 0"/>
  </joint>
  <!-- Sensor coordinate frame pointing opposite direction of connector at the bottom of the sensor -->
  <link name="nominal_tractor_lidar_rear">
    <inertial>
      <mass value="0.00002"/>
      <origin xyz="0 0 0.03585"/>
      <inertia ixx="2.1880950000000003e-08" ixy="0" ixz="0" iyy="2.1880950000000003e-08" iyz="0" izz="2.66256e-08"/>
    </inertial>
    <visual>
      <origin rpy="1.5708 0 -1.5708" xyz="0 0 0"/>
      <geometry>
        <mesh filename="file:///home/ros/ws/common_ws/install/sensor_description/share/sensor_description/models/ouster_OS0-128/meshes/OS0.dae"/>
      </geometry>
    </visual>
    <collision>
      <origin rpy="0 0 0" xyz="0 0 0.03585"/>
      <geometry>
        <cylinder length="0.0717" radius="0.0516"/>
      </geometry>
    </collision>
  </link>
  <joint name="nominal_tractor_lidar_rear_joint" type="fixed">
    <origin rpy="0 0 3.141592653589793" xyz="0 0 0.0025"/>
    <parent link="rear_top_mount"/>
    <child link="nominal_tractor_lidar_rear"/>
  </joint>
  <link name="tractor_lidar_rear/laser"/>
  <joint name="tractor_lidar_rear_laser" type="fixed">
    <origin rpy="0.0 0.0 3.14" xyz="0 0 36.180e-3"/>
    <parent link="tractor_lidar_rear"/>
    <child link="tractor_lidar_rear/laser"/>
  </joint>
  <link name="tractor_lidar_rear/imu"/>
  <joint name="tractor_lidar_rear_imu" type="fixed">
    <origin rpy="0.0 0.0 0.0" xyz="6.253e-3 -11.775e-3 7.645e-3"/>
    <parent link="tractor_lidar_rear"/>
    <child link="tractor_lidar_rear/imu"/>
  </joint>
  <link name="tractor_lidar_rear">
    <inertial>
      <mass value="0.0005"/>
      <origin rpy=" 0 0 0" xyz="0 0 0"/>
      <inertia ixx="0.001" ixy="0" ixz="0" iyy="0.001" iyz="0" izz="0.001"/>
    </inertial>
  </link>
  <joint name="nominal_tractor_lidar_rear_tractor_lidar_rear_joint" type="fixed">
    <parent link="nominal_tractor_lidar_rear"/>
    <child link="tractor_lidar_rear"/>
    <origin rpy="0 0.03 0" xyz="0 0 0"/>
  </joint>
  <link name="nominal_tractor_camera_mount_front">
    <inertial>
      <mass value="0.0005"/>
      <origin rpy=" 0 0 0" xyz="0 0 0"/>
      <inertia ixx="0.001" ixy="0" ixz="0" iyy="0.001" iyz="0" izz="0.001"/>
    </inertial>
    <collision name="nominal_tractor_camera_mount_front_collision">
      <origin rpy=" 0 0 0" xyz="0 0 0"/>
      <geometry>
        <mesh filename="file:///home/ros/ws/common_ws/install/sensor_description/share/sensor_description/models/arkvision_arkcam_mini/meshes/ark_cam_basic_red.dae" scale="0.001 0.001 0.001"/>
      </geometry>
    </collision>
    <visual>
      <origin rpy="0 0 0" xyz="0 0 0"/>
      <geometry>
        <mesh filename="file:///home/ros/ws/common_ws/install/sensor_description/share/sensor_description/models/arkvision_arkcam_mini/meshes/ark_cam_basic_red.dae" scale="0.001 0.001 0.001"/>
      </geometry>
    </visual>
  </link>
  <joint name="nominal_tractor_camera_mount_front_joint" type="fixed">
    <origin rpy="0 0 0" xyz="0.042 0 0"/>
    <parent link="ark_cam_mini_bracket_front"/>
    <child link="nominal_tractor_camera_mount_front"/>
  </joint>
  <link name="nominal_tractor_camera_front">
    <inertial>
      <mass value="0.0005"/>
      <origin rpy=" 0 0 0" xyz="0 0 0"/>
      <inertia ixx="0.001" ixy="0" ixz="0" iyy="0.001" iyz="0" izz="0.001"/>
    </inertial>
  </link>
  <joint name="nominal_tractor_camera_front_joint" type="fixed">
    <origin rpy="0 0 0" xyz="0.015 0 0"/>
    <parent link="nominal_tractor_camera_mount_front"/>
    <child link="nominal_tractor_camera_front"/>
  </joint>
  <link name="nominal_tractor_camera_front_optical_frame">
    <inertial>
      <mass value="0.0005"/>
      <origin rpy=" 0 0 0" xyz="0 0 0"/>
      <inertia ixx="0.001" ixy="0" ixz="0" iyy="0.001" iyz="0" izz="0.001"/>
    </inertial>
  </link>
  <joint name="nominal_tractor_camera_front_optical_joint" type="fixed">
    <origin rpy="0 0 0" xyz="0 0 0"/>
    <parent link="nominal_tractor_camera_front"/>
    <child link="nominal_tractor_camera_front_optical_frame"/>
  </joint>
  <link name="tractor_camera_front_optical_frame">
    <inertial>
      <mass value="0.0005"/>
      <origin rpy=" 0 0 0" xyz="0 0 0"/>
      <inertia ixx="0.001" ixy="0" ixz="0" iyy="0.001" iyz="0" izz="0.001"/>
    </inertial>
  </link>
  <joint name="nominal_tractor_camera_front_optical_frame_tractor_camera_front_optical_frame_joint" type="fixed">
    <parent link="nominal_tractor_camera_front_optical_frame"/>
    <child link="tractor_camera_front_optical_frame"/>
    <origin rpy="0 0 0" xyz="0 0 0"/>
  </joint>
  <link name="nominal_tractor_camera_bracket_middle_right">
    <inertial>
      <mass value="0.0005"/>
      <origin rpy=" 0 0 0" xyz="0 0 0"/>
      <inertia ixx="0.001" ixy="0" ixz="0" iyy="0.001" iyz="0" izz="0.001"/>
    </inertial>
    <collision name="nominal_tractor_camera_bracket_middle_right_collision">
      <origin rpy=" 0 0 0" xyz="0 0 0"/>
      <geometry>
        <box size="0.05 0.05 0.05"/>
      </geometry>
    </collision>
    <visual>
      <origin rpy="1.57079 0 1.57079" xyz="0 0 0"/>
      <geometry>
        <mesh filename="file:///home/ros/ws/common_ws/install/sensor_description/share/sensor_description/models/arkvision_arkcam_mini/meshes/ark_cam_basic_bracket_red.dae" scale="0.001 0.001 0.001"/>
      </geometry>
    </visual>
  </link>
  <joint name="nominal_tractor_camera_bracket_middle_right_joint" type="fixed">
    <origin rpy="0 0 -1.5708" xyz="0.31 -0.85 0.0"/>
    <parent link="roof_base"/>
    <child link="nominal_tractor_camera_bracket_middle_right"/>
  </joint>
  <link name="nominal_tractor_camera_mount_middle_right">
    <inertial>
      <mass value="0.0005"/>
      <origin rpy=" 0 0 0" xyz="0 0 0"/>
      <inertia ixx="0.001" ixy="0" ixz="0" iyy="0.001" iyz="0" izz="0.001"/>
    </inertial>
    <collision name="nominal_tractor_camera_mount_middle_right_collision">
      <origin rpy=" 0 0 0" xyz="0 0 0"/>
      <geometry>
        <mesh filename="file:///home/ros/ws/common_ws/install/sensor_description/share/sensor_description/models/arkvision_arkcam_mini/meshes/ark_cam_basic_red.dae" scale="0.001 0.001 0.001"/>
      </geometry>
    </collision>
    <visual>
      <origin rpy="0 0 0" xyz="0 0 0"/>
      <geometry>
        <mesh filename="file:///home/ros/ws/common_ws/install/sensor_description/share/sensor_description/models/arkvision_arkcam_mini/meshes/ark_cam_basic_red.dae" scale="0.001 0.001 0.001"/>
      </geometry>
    </visual>
  </link>
  <joint name="nominal_tractor_camera_mount_middle_right_joint" type="fixed">
    <origin rpy="0 0.7 0" xyz="0.042 0 0"/>
    <parent link="nominal_tractor_camera_bracket_middle_right"/>
    <child link="nominal_tractor_camera_mount_middle_right"/>
  </joint>
  <link name="nominal_tractor_camera_middle_right">
    <inertial>
      <mass value="0.0005"/>
      <origin rpy=" 0 0 0" xyz="0 0 0"/>
      <inertia ixx="0.001" ixy="0" ixz="0" iyy="0.001" iyz="0" izz="0.001"/>
    </inertial>
  </link>
  <joint name="nominal_tractor_camera_middle_right_joint" type="fixed">
    <origin rpy="0 0 0" xyz="0.015 0 0"/>
    <parent link="nominal_tractor_camera_mount_middle_right"/>
    <child link="nominal_tractor_camera_middle_right"/>
  </joint>
  <link name="nominal_tractor_camera_middle_right_optical_frame">
    <inertial>
      <mass value="0.0005"/>
      <origin rpy=" 0 0 0" xyz="0 0 0"/>
      <inertia ixx="0.001" ixy="0" ixz="0" iyy="0.001" iyz="0" izz="0.001"/>
    </inertial>
  </link>
  <joint name="nominal_tractor_camera_middle_right_optical_joint" type="fixed">
    <origin rpy="0 0 0" xyz="0 0 0"/>
    <parent link="nominal_tractor_camera_middle_right"/>
    <child link="nominal_tractor_camera_middle_right_optical_frame"/>
  </joint>
  <link name="tractor_camera_middle_right_optical_frame">
    <inertial>
      <mass value="0.0005"/>
      <origin rpy=" 0 0 0" xyz="0 0 0"/>
      <inertia ixx="0.001" ixy="0" ixz="0" iyy="0.001" iyz="0" izz="0.001"/>
    </inertial>
  </link>
  <joint name="nominal_tractor_camera_middle_right_optical_frame_tractor_camera_middle_right_optical_frame_joint" type="fixed">
    <parent link="nominal_tractor_camera_middle_right_optical_frame"/>
    <child link="tractor_camera_middle_right_optical_frame"/>
    <origin rpy="0 0 0" xyz="0 0 0"/>
  </joint>
  <!-- camera plugin-->
  <gazebo reference="">
    <sensor name="tractor_camera_middle_right" type="wideanglecamera">
      <update_rate>5.0</update_rate>
      <camera name="head_middle_right">
        <horizontal_fov>3.0</horizontal_fov>
        <image>
          <width>640</width>
          <height>480</height>
          <format>R8G8B8</format>
        </image>
        <clip>
          <near>0.02</near>
          <far>300</far>
        </clip>
        <lens>
          <!-- type element is mandatory -->
          <type>custom</type>
          <!-- manually defined mapping function r = c1*f*fun(theta/c2 + c3) -->
          <!-- More information here https://en.wikipedia.org/wiki/Fisheye_lens#Mapping_function -->
          <custom_function>
            <c1>1.05</c1>
            <!-- linear scaling -->
            <c2>4</c2>
            <!-- angle scaling -->
            <f>1.0</f>
            <!-- one more scaling parameter -->
            <fun>tan</fun>
            <!-- one of sin,tan,id -->
          </custom_function>
          <!-- if it is set to `true` your horizontal FOV will ramain as defined -->
          <!-- othervise it depends on lens type and custom function, if there is one -->
          <scale_to_hfov>true</scale_to_hfov>
          <!-- clip everything that is outside of this angle -->
          <cutoff_angle>3.0</cutoff_angle>
          <!-- resolution of the cubemap texture, the highter it is - the sharper is your image -->
          <env_texture_size>512</env_texture_size>
        </lens>
      </camera>
      <plugin filename="libgazebo_ros_camera.so" name="middle_right">
        <ros>
          <namespace>tractor/camera</namespace>
        </ros>
        <alwaysOn>true</alwaysOn>
        <updateRate>5.0</updateRate>
        <camera_name>middle_right</camera_name>
        <imageTopicName>rgb/image_raw</imageTopicName>
        <cameraInfoTopicName>rgb/camera_info</cameraInfoTopicName>
        <frameName></frameName>
        <hackBaseline>0.07</hackBaseline>
        <!--distortionK1>0.0</distortionK1>
                                        <distortionK2>0.0</distortionK2>
                                        <distortionK3>0.0</distortionK3>
                                        <distortionT1>0.0</distortionT1>
                                        <distortionT2>0.0</distortionT2-->
      </plugin>
    </sensor>
  </gazebo>
  <link name="nominal_tractor_camera_bracket_middle_left">
    <inertial>
      <mass value="0.0005"/>
      <origin rpy=" 0 0 0" xyz="0 0 0"/>
      <inertia ixx="0.001" ixy="0" ixz="0" iyy="0.001" iyz="0" izz="0.001"/>
    </inertial>
    <collision name="nominal_tractor_camera_bracket_middle_left_collision">
      <origin rpy=" 0 0 0" xyz="0 0 0"/>
      <geometry>
        <box size="0.05 0.05 0.05"/>
      </geometry>
    </collision>
    <visual>
      <origin rpy="1.57079 0 1.57079" xyz="0 0 0"/>
      <geometry>
        <mesh filename="file:///home/ros/ws/common_ws/install/sensor_description/share/sensor_description/models/arkvision_arkcam_mini/meshes/ark_cam_basic_bracket_red.dae" scale="0.001 0.001 0.001"/>
      </geometry>
    </visual>
  </link>
  <joint name="nominal_tractor_camera_bracket_middle_left_joint" type="fixed">
    <origin rpy="0 0 1.5708" xyz="0.31 0.85 0.0"/>
    <parent link="roof_base"/>
    <child link="nominal_tractor_camera_bracket_middle_left"/>
  </joint>
  <link name="nominal_tractor_camera_mount_middle_left">
    <inertial>
      <mass value="0.0005"/>
      <origin rpy=" 0 0 0" xyz="0 0 0"/>
      <inertia ixx="0.001" ixy="0" ixz="0" iyy="0.001" iyz="0" izz="0.001"/>
    </inertial>
    <collision name="nominal_tractor_camera_mount_middle_left_collision">
      <origin rpy=" 0 0 0" xyz="0 0 0"/>
      <geometry>
        <mesh filename="file:///home/ros/ws/common_ws/install/sensor_description/share/sensor_description/models/arkvision_arkcam_mini/meshes/ark_cam_basic_red.dae" scale="0.001 0.001 0.001"/>
      </geometry>
    </collision>
    <visual>
      <origin rpy="0 0 0" xyz="0 0 0"/>
      <geometry>
        <mesh filename="file:///home/ros/ws/common_ws/install/sensor_description/share/sensor_description/models/arkvision_arkcam_mini/meshes/ark_cam_basic_red.dae" scale="0.001 0.001 0.001"/>
      </geometry>
    </visual>
  </link>
  <joint name="nominal_tractor_camera_mount_middle_left_joint" type="fixed">
    <origin rpy="0 0.7 0" xyz="0.042 0 0"/>
    <parent link="nominal_tractor_camera_bracket_middle_left"/>
    <child link="nominal_tractor_camera_mount_middle_left"/>
  </joint>
  <link name="nominal_tractor_camera_middle_left">
    <inertial>
      <mass value="0.0005"/>
      <origin rpy=" 0 0 0" xyz="0 0 0"/>
      <inertia ixx="0.001" ixy="0" ixz="0" iyy="0.001" iyz="0" izz="0.001"/>
    </inertial>
  </link>
  <joint name="nominal_tractor_camera_middle_left_joint" type="fixed">
    <origin rpy="0 0 0" xyz="0.015 0 0"/>
    <parent link="nominal_tractor_camera_mount_middle_left"/>
    <child link="nominal_tractor_camera_middle_left"/>
  </joint>
  <link name="nominal_tractor_camera_middle_left_optical_frame">
    <inertial>
      <mass value="0.0005"/>
      <origin rpy=" 0 0 0" xyz="0 0 0"/>
      <inertia ixx="0.001" ixy="0" ixz="0" iyy="0.001" iyz="0" izz="0.001"/>
    </inertial>
  </link>
  <joint name="nominal_tractor_camera_middle_left_optical_joint" type="fixed">
    <origin rpy="0 0 0" xyz="0 0 0"/>
    <parent link="nominal_tractor_camera_middle_left"/>
    <child link="nominal_tractor_camera_middle_left_optical_frame"/>
  </joint>
  <link name="tractor_camera_middle_left_optical_frame">
    <inertial>
      <mass value="0.0005"/>
      <origin rpy=" 0 0 0" xyz="0 0 0"/>
      <inertia ixx="0.001" ixy="0" ixz="0" iyy="0.001" iyz="0" izz="0.001"/>
    </inertial>
  </link>
  <joint name="nominal_tractor_camera_middle_left_optical_frame_tractor_camera_middle_left_optical_frame_joint" type="fixed">
    <parent link="nominal_tractor_camera_middle_left_optical_frame"/>
    <child link="tractor_camera_middle_left_optical_frame"/>
    <origin rpy="0 0 0" xyz="0 0 0"/>
  </joint>
  <link name="nominal_tractor_camera_mount_rear">
    <inertial>
      <mass value="0.0005"/>
      <origin rpy=" 0 0 0" xyz="0 0 0"/>
      <inertia ixx="0.001" ixy="0" ixz="0" iyy="0.001" iyz="0" izz="0.001"/>
    </inertial>
    <collision name="nominal_tractor_camera_mount_rear_collision">
      <origin rpy=" 0 0 0" xyz="0 0 0"/>
      <geometry>
        <mesh filename="file:///home/ros/ws/common_ws/install/sensor_description/share/sensor_description/models/arkvision_arkcam_mini/meshes/ark_cam_basic_red.dae" scale="0.001 0.001 0.001"/>
      </geometry>
    </collision>
    <visual>
      <origin rpy="0 0 0" xyz="0 0 0"/>
      <geometry>
        <mesh filename="file:///home/ros/ws/common_ws/install/sensor_description/share/sensor_description/models/arkvision_arkcam_mini/meshes/ark_cam_basic_red.dae" scale="0.001 0.001 0.001"/>
      </geometry>
    </visual>
  </link>
  <joint name="nominal_tractor_camera_mount_rear_joint" type="fixed">
    <origin rpy="0 0 0" xyz="0.042 0 0"/>
    <parent link="ark_cam_mini_bracket_rear"/>
    <child link="nominal_tractor_camera_mount_rear"/>
  </joint>
  <link name="nominal_tractor_camera_rear">
    <inertial>
      <mass value="0.0005"/>
      <origin rpy=" 0 0 0" xyz="0 0 0"/>
      <inertia ixx="0.001" ixy="0" ixz="0" iyy="0.001" iyz="0" izz="0.001"/>
    </inertial>
  </link>
  <joint name="nominal_tractor_camera_rear_joint" type="fixed">
    <origin rpy="0 0 0" xyz="0.015 0 0"/>
    <parent link="nominal_tractor_camera_mount_rear"/>
    <child link="nominal_tractor_camera_rear"/>
  </joint>
  <link name="nominal_tractor_camera_rear_optical_frame">
    <inertial>
      <mass value="0.0005"/>
      <origin rpy=" 0 0 0" xyz="0 0 0"/>
      <inertia ixx="0.001" ixy="0" ixz="0" iyy="0.001" iyz="0" izz="0.001"/>
    </inertial>
  </link>
  <joint name="nominal_tractor_camera_rear_optical_joint" type="fixed">
    <origin rpy="0 0 0" xyz="0 0 0"/>
    <parent link="nominal_tractor_camera_rear"/>
    <child link="nominal_tractor_camera_rear_optical_frame"/>
  </joint>
  <link name="tractor_camera_rear_optical_frame">
    <inertial>
      <mass value="0.0005"/>
      <origin rpy=" 0 0 0" xyz="0 0 0"/>
      <inertia ixx="0.001" ixy="0" ixz="0" iyy="0.001" iyz="0" izz="0.001"/>
    </inertial>
  </link>
  <joint name="nominal_tractor_camera_rear_optical_frame_tractor_camera_rear_optical_frame_joint" type="fixed">
    <parent link="nominal_tractor_camera_rear_optical_frame"/>
    <child link="tractor_camera_rear_optical_frame"/>
    <origin rpy="0 0 0" xyz="0 0 0"/>
  </joint>
  <!-- Radar links and joints -->
  <link name="nominal_tractor_radar_front_left">
    <inertial>
      <mass value="0.0005"/>
      <origin rpy=" 0 0 0" xyz="0 0 0"/>
      <inertia ixx="0.001" ixy="0" ixz="0" iyy="0.001" iyz="0" izz="0.001"/>
    </inertial>
    <collision name="nominal_tractor_radar_front_left_collision">
      <origin rpy=" 0 0 0" xyz="0 0 0"/>
      <geometry>
        <box size="0.02 0.1 0.1"/>
      </geometry>
    </collision>
    <visual name="nominal_tractor_radar_front_left_visual">
      <origin rpy=" 0 1.57079 -1.57079" xyz="0 -0.002 0"/>
      <geometry>
        <!--box size="0.02 0.1 0.1"/-->
        <mesh filename="file:///home/ros/ws/common_ws/install/sensor_description/share/sensor_description/models/smartmicro_type153/meshes/smartmicro_type153.dae" scale="1.0 1.0 1.0"/>
      </geometry>
    </visual>
  </link>
  <joint name="nominal_tractor_radar_front_left_joint" type="fixed">
    <origin rpy="3.141592653589793 0.17 0.79" xyz="4.7 0.2 -0.030000000000000027"/>
    <parent link="tractor_chassis"/>
    <child link="nominal_tractor_radar_front_left"/>
  </joint>
  <link name="nominal_tractor_radar_front_left_optical_frame">
    <inertial>
      <mass value="0.0005"/>
      <origin rpy=" 0 0 0" xyz="0 0 0"/>
      <inertia ixx="0.001" ixy="0" ixz="0" iyy="0.001" iyz="0" izz="0.001"/>
    </inertial>
  </link>
  <joint name="nominal_tractor_radar_front_left_optical_joint" type="fixed">
    <origin rpy="-1.57 0 -1.57" xyz="0 0 0"/>
    <parent link="nominal_tractor_radar_front_left"/>
    <child link="nominal_tractor_radar_front_left_optical_frame"/>
  </joint>
  <link name="tractor_radar_front_left">
    <inertial>
      <mass value="0.0005"/>
      <origin rpy=" 0 0 0" xyz="0 0 0"/>
      <inertia ixx="0.001" ixy="0" ixz="0" iyy="0.001" iyz="0" izz="0.001"/>
    </inertial>
  </link>
  <joint name="nominal_tractor_radar_front_right_tractor_radar_front_left_joint" type="fixed">
    <parent link="nominal_tractor_radar_front_right"/>
    <child link="tractor_radar_front_left"/>
    <origin rpy="3.14159265359 -0.3 0" xyz="0 0 -1.0"/>
  </joint>
  <!-- Radar links and joints -->
  <link name="nominal_tractor_radar_front_right">
    <inertial>
      <mass value="0.0005"/>
      <origin rpy=" 0 0 0" xyz="0 0 0"/>
      <inertia ixx="0.001" ixy="0" ixz="0" iyy="0.001" iyz="0" izz="0.001"/>
    </inertial>
    <collision name="nominal_tractor_radar_front_right_collision">
      <origin rpy=" 0 0 0" xyz="0 0 0"/>
      <geometry>
        <box size="0.02 0.1 0.1"/>
      </geometry>
    </collision>
    <visual name="nominal_tractor_radar_front_right_visual">
      <origin rpy=" 0 1.57079 -1.57079" xyz="0 -0.002 0"/>
      <geometry>
        <!--box size="0.02 0.1 0.1"/-->
        <mesh filename="file:///home/ros/ws/common_ws/install/sensor_description/share/sensor_description/models/smartmicro_type153/meshes/smartmicro_type153.dae" scale="1.0 1.0 1.0"/>
      </geometry>
    </visual>
  </link>
  <joint name="nominal_tractor_radar_front_right_joint" type="fixed">
    <origin rpy="0 0.17 -0.79" xyz="4.7 -0.2 -0.030000000000000027"/>
    <parent link="tractor_chassis"/>
    <child link="nominal_tractor_radar_front_right"/>
  </joint>
  <link name="nominal_tractor_radar_front_right_optical_frame">
    <inertial>
      <mass value="0.0005"/>
      <origin rpy=" 0 0 0" xyz="0 0 0"/>
      <inertia ixx="0.001" ixy="0" ixz="0" iyy="0.001" iyz="0" izz="0.001"/>
    </inertial>
  </link>
  <joint name="nominal_tractor_radar_front_right_optical_joint" type="fixed">
    <origin rpy="-1.57 0 -1.57" xyz="0 0 0"/>
    <parent link="nominal_tractor_radar_front_right"/>
    <child link="nominal_tractor_radar_front_right_optical_frame"/>
  </joint>
  <link name="tractor_radar_front_right">
    <inertial>
      <mass value="0.0005"/>
      <origin rpy=" 0 0 0" xyz="0 0 0"/>
      <inertia ixx="0.001" ixy="0" ixz="0" iyy="0.001" iyz="0" izz="0.001"/>
    </inertial>
  </link>
  <joint name="nominal_tractor_radar_front_left_tractor_radar_front_right_joint" type="fixed">
    <parent link="nominal_tractor_radar_front_left"/>
    <child link="tractor_radar_front_right"/>
    <origin rpy="3.14159265359 0.12 0" xyz="0 0 -0.2"/>
  </joint>
  <!-- Radar links and joints -->
  <link name="nominal_tractor_radar_middle_left">
    <inertial>
      <mass value="0.0005"/>
      <origin rpy=" 0 0 0" xyz="0 0 0"/>
      <inertia ixx="0.001" ixy="0" ixz="0" iyy="0.001" iyz="0" izz="0.001"/>
    </inertial>
    <collision name="nominal_tractor_radar_middle_left_collision">
      <origin rpy=" 0 0 0" xyz="0 0 0"/>
      <geometry>
        <box size="0.02 0.1 0.1"/>
      </geometry>
    </collision>
    <visual name="nominal_tractor_radar_middle_left_visual">
      <origin rpy=" 0 1.57079 -1.57079" xyz="0 -0.002 0"/>
      <geometry>
        <!--box size="0.02 0.1 0.1"/-->
        <mesh filename="file:///home/ros/ws/common_ws/install/sensor_description/share/sensor_description/models/smartmicro_type153/meshes/smartmicro_type153.dae" scale="1.0 1.0 1.0"/>
      </geometry>
    </visual>
  </link>
  <joint name="nominal_tractor_radar_middle_left_joint" type="fixed">
    <origin rpy="0.0 0.35 1.57079633" xyz="1.3 1.05 0.44999999999999996"/>
    <parent link="tractor_chassis"/>
    <child link="nominal_tractor_radar_middle_left"/>
  </joint>
  <link name="nominal_tractor_radar_middle_left_optical_frame">
    <inertial>
      <mass value="0.0005"/>
      <origin rpy=" 0 0 0" xyz="0 0 0"/>
      <inertia ixx="0.001" ixy="0" ixz="0" iyy="0.001" iyz="0" izz="0.001"/>
    </inertial>
  </link>
  <joint name="nominal_tractor_radar_middle_left_optical_joint" type="fixed">
    <origin rpy="-1.57 0 -1.57" xyz="0 0 0"/>
    <parent link="nominal_tractor_radar_middle_left"/>
    <child link="nominal_tractor_radar_middle_left_optical_frame"/>
  </joint>
  <link name="tractor_radar_middle_left">
    <inertial>
      <mass value="0.0005"/>
      <origin rpy=" 0 0 0" xyz="0 0 0"/>
      <inertia ixx="0.001" ixy="0" ixz="0" iyy="0.001" iyz="0" izz="0.001"/>
    </inertial>
  </link>
  <joint name="nominal_tractor_radar_middle_left_tractor_radar_middle_left_joint" type="fixed">
    <parent link="nominal_tractor_radar_middle_left"/>
    <child link="tractor_radar_middle_left"/>
    <origin rpy="0 -0.32 0" xyz="0 0 -0.2"/>
  </joint>
  <!-- Radar links and joints -->
  <link name="nominal_tractor_radar_middle_right">
    <inertial>
      <mass value="0.0005"/>
      <origin rpy=" 0 0 0" xyz="0 0 0"/>
      <inertia ixx="0.001" ixy="0" ixz="0" iyy="0.001" iyz="0" izz="0.001"/>
    </inertial>
    <collision name="nominal_tractor_radar_middle_right_collision">
      <origin rpy=" 0 0 0" xyz="0 0 0"/>
      <geometry>
        <box size="0.02 0.1 0.1"/>
      </geometry>
    </collision>
    <visual name="nominal_tractor_radar_middle_right_visual">
      <origin rpy=" 0 1.57079 -1.57079" xyz="0 -0.002 0"/>
      <geometry>
        <!--box size="0.02 0.1 0.1"/-->
        <mesh filename="file:///home/ros/ws/common_ws/install/sensor_description/share/sensor_description/models/smartmicro_type153/meshes/smartmicro_type153.dae" scale="1.0 1.0 1.0"/>
      </geometry>
    </visual>
  </link>
  <joint name="nominal_tractor_radar_middle_right_joint" type="fixed">
    <origin rpy="3.141592653589793 0.35 -1.57079633" xyz="1.3 -1.05 0.44999999999999996"/>
    <parent link="tractor_chassis"/>
    <child link="nominal_tractor_radar_middle_right"/>
  </joint>
  <link name="nominal_tractor_radar_middle_right_optical_frame">
    <inertial>
      <mass value="0.0005"/>
      <origin rpy=" 0 0 0" xyz="0 0 0"/>
      <inertia ixx="0.001" ixy="0" ixz="0" iyy="0.001" iyz="0" izz="0.001"/>
    </inertial>
  </link>
  <joint name="nominal_tractor_radar_middle_right_optical_joint" type="fixed">
    <origin rpy="-1.57 0 -1.57" xyz="0 0 0"/>
    <parent link="nominal_tractor_radar_middle_right"/>
    <child link="nominal_tractor_radar_middle_right_optical_frame"/>
  </joint>
  <link name="tractor_radar_middle_right">
    <inertial>
      <mass value="0.0005"/>
      <origin rpy=" 0 0 0" xyz="0 0 0"/>
      <inertia ixx="0.001" ixy="0" ixz="0" iyy="0.001" iyz="0" izz="0.001"/>
    </inertial>
  </link>
  <joint name="nominal_tractor_radar_middle_right_tractor_radar_middle_right_joint" type="fixed">
    <parent link="nominal_tractor_radar_middle_right"/>
    <child link="tractor_radar_middle_right"/>
    <origin rpy="0 0.3 0" xyz="0 0 0.6"/>
  </joint>
  <link name="tractor_gnss_right_mount">
    <inertial>
      <mass value="0.0005"/>
      <origin rpy=" 0 0 0" xyz="0 0 0"/>
      <inertia ixx="0.001" ixy="0" ixz="0" iyy="0.001" iyz="0" izz="0.001"/>
    </inertial>
    <collision>
      <origin rpy=" 0 0 0" xyz="0 0 0"/>
      <geometry>
        <cylinder length="0.05" radius="0.1"/>
      </geometry>
    </collision>
    <visual>
      <origin rpy="1.57 0 -1.57" xyz="0 0 0"/>
      <geometry>
        <mesh filename="file:///home/ros/ws/common_ws/install/sensor_description/share/sensor_description/models/novatel_smart7/meshes/smart7.stl" scale="0.001 0.001 0.001"/>
      </geometry>
    </visual>
  </link>
  <joint name="tractor_gnss_right_mount_joint" type="fixed">
    <parent link="roof_base"/>
    <child link="tractor_gnss_right_mount"/>
    <origin rpy="0 0 0" xyz="0.31 -0.835 0.1"/>
  </joint>
  <link name="tractor_gnss_right_center">
    <inertial>
      <mass value="0.0005"/>
      <origin rpy=" 0 0 0" xyz="0 0 0"/>
      <inertia ixx="0.001" ixy="0" ixz="0" iyy="0.001" iyz="0" izz="0.001"/>
    </inertial>
    <collision>
      <origin rpy=" 0 0 0" xyz="0 0 0"/>
      <geometry>
        <cylinder length="0.05" radius="0.1"/>
      </geometry>
    </collision>
  </link>
  <joint name="tractor_gnss_right_joint" type="fixed">
    <parent link="tractor_gnss_right_mount"/>
    <child link="tractor_gnss_right_center"/>
    <origin rpy=" 0 0 0" xyz="0.07 0 0.0569"/>
  </joint>
  <link name="tractor_gnss_right_imu">
    <inertial>
      <mass value="0.0005"/>
      <origin rpy=" 0 0 0" xyz="0 0 0"/>
      <inertia ixx="0.001" ixy="0" ixz="0" iyy="0.001" iyz="0" izz="0.001"/>
    </inertial>
    <collision>
      <origin rpy=" 0 0 0" xyz="0 0 0"/>
      <geometry>
        <cylinder length="0.05" radius="0.1"/>
      </geometry>
    </collision>
  </link>
  <joint name="tractor_gnss_right_imu_joint" type="fixed">
    <parent link="tractor_gnss_right_center"/>
    <child link="tractor_gnss_right_imu"/>
    <origin rpy="0.0 0 0" xyz="0.0 0 0.0"/>
  </joint>
  <link name="tractor_gnss_left_mount">
    <inertial>
      <mass value="0.0005"/>
      <origin rpy=" 0 0 0" xyz="0 0 0"/>
      <inertia ixx="0.001" ixy="0" ixz="0" iyy="0.001" iyz="0" izz="0.001"/>
    </inertial>
    <collision>
      <origin rpy=" 0 0 0" xyz="0 0 0"/>
      <geometry>
        <cylinder length="0.05" radius="0.1"/>
      </geometry>
    </collision>
    <visual>
      <origin rpy="1.57 0 -1.57" xyz="0 0 0"/>
      <geometry>
        <mesh filename="file:///home/ros/ws/common_ws/install/sensor_description/share/sensor_description/models/novatel_smart7/meshes/smart7.stl" scale="0.001 0.001 0.001"/>
      </geometry>
    </visual>
  </link>
  <joint name="tractor_gnss_left_mount_joint" type="fixed">
    <parent link="roof_base"/>
    <child link="tractor_gnss_left_mount"/>
    <origin rpy="0 0 0" xyz="0.31 0.835 0.1"/>
  </joint>
  <link name="tractor_gnss_left_center">
    <inertial>
      <mass value="0.0005"/>
      <origin rpy=" 0 0 0" xyz="0 0 0"/>
      <inertia ixx="0.001" ixy="0" ixz="0" iyy="0.001" iyz="0" izz="0.001"/>
    </inertial>
    <collision>
      <origin rpy=" 0 0 0" xyz="0 0 0"/>
      <geometry>
        <cylinder length="0.05" radius="0.1"/>
      </geometry>
    </collision>
  </link>
  <joint name="tractor_gnss_left_joint" type="fixed">
    <parent link="tractor_gnss_left_mount"/>
    <child link="tractor_gnss_left_center"/>
    <origin rpy=" 0 0 0" xyz="0.07 0 0.0569"/>
  </joint>
  <link name="tractor_gnss_left_imu">
    <inertial>
      <mass value="0.0005"/>
      <origin rpy=" 0 0 0" xyz="0 0 0"/>
      <inertia ixx="0.001" ixy="0" ixz="0" iyy="0.001" iyz="0" izz="0.001"/>
    </inertial>
    <collision>
      <origin rpy=" 0 0 0" xyz="0 0 0"/>
      <geometry>
        <cylinder length="0.05" radius="0.1"/>
      </geometry>
    </collision>
  </link>
  <joint name="tractor_gnss_left_imu_joint" type="fixed">
    <parent link="tractor_gnss_left_center"/>
    <child link="tractor_gnss_left_imu"/>
    <origin rpy="0.0 0 0" xyz="0.0 0 0.0"/>
  </joint>
  <link name="tractor_gnss_autotrac_link">
    <inertial>
      <mass value="0.0005"/>
      <origin rpy=" 0 0 0" xyz="0 0 0"/>
      <inertia ixx="0.001" ixy="0" ixz="0" iyy="0.001" iyz="0" izz="0.001"/>
    </inertial>
    <collision>
      <origin rpy=" 0 0 0" xyz="0 0 0"/>
      <geometry>
        <cylinder length="0.05" radius="0.1"/>
      </geometry>
    </collision>
    <visual>
      <origin rpy=" 0 0 0" xyz="0 0 0"/>
      <geometry>
        <mesh filename="file:///home/ros/ws/common_ws/install/sensor_description/share/sensor_description/models/generic_gnss/meshes/generic_gnss.dae"/>
      </geometry>
    </visual>
  </link>
  <joint name="tractor_gnss_autotrac_joint" type="fixed">
    <parent link="roof_base"/>
    <child link="tractor_gnss_autotrac_link"/>
    <origin rpy="0 0 0" xyz="1.21 0 0.1"/>
  </joint>
  <link name="tractor_imu_center">
    <inertial>
      <mass value="0.0005"/>
      <origin rpy=" 0 0 0" xyz="0 0 0"/>
      <inertia ixx="0.001" ixy="0" ixz="0" iyy="0.001" iyz="0" izz="0.001"/>
    </inertial>
    <visual>
      <origin rpy=" 0 0 0" xyz="0 0 0"/>
      <geometry>
        <box size="0.05 0.05 0.05"/>
      </geometry>
    </visual>
  </link>
  <joint name="tractor_imu_center_joint" type="fixed">
    <origin rpy="0 0 0" xyz="0 0 0.25"/>
    <parent link="tractor_chassis"/>
    <child link="tractor_imu_center"/>
    <origin rpy="0 0 0" xyz="0 0 0.25"/>
  </joint>
</robot>
