<robot name="fort_rd25">
  
  <link name="base_link">
        </link>
  
  <link name="tractor_chassis">
    <visual>
      <origin rpy="0.0 0.0 1.57" xyz="0.0 0.28 0.0" />
      <geometry>
        <mesh filename="https://raw.githubusercontent.com/CM134/urdf-test/main/meshes/fort_rd25.dae" />
      </geometry>
      <material name="grey">
        <color rgba="0.2 0.2 0.2 1.0" />
      </material>
    </visual>
    <collision>
      <origin rpy="0.0 0.0 1.57" xyz="0.0 0.28 0.0" />
      <geometry>
        <mesh filename="https://raw.githubusercontent.com/CM134/urdf-test/main/meshes/fort_rd25.dae" />
      </geometry>
    </collision>
    <inertial>
      <origin rpy="1.5707963267948966 0 1.5707963267948966" xyz="0 0 0" />
      <mass value="500.0" />
      <inertia ixx="186.3375" ixy="0.0" ixz="0.0" iyy="154.26666666666668" iyz="0.0" izz="70.60416666666667" />
    </inertial>
  </link>
  <joint name="base_link_to_chassis" type="fixed">
    <parent link="base_link" />
    <child link="tractor_chassis" />
    <origin rpy="0.0 0.0 0.0" xyz="0.0 0.0 0.0" />
  </joint>
  <link name="tractor_right_wheel">
    <collision>
      
      <origin rpy="1.57079633 0 0" xyz="0 0 0" />
      <geometry>
        <cylinder length="0.1" radius="0.34" />
      </geometry>
      <surface>
        <friction>
          <ode>
            <mu>1</mu>
            <mu2>0.25</mu2>
            <slip1>0.00001</slip1>
            <slip2>0.00001</slip2>
          </ode>
        </friction>
        <contact>
          <ode>
            <soft_cfm>0</soft_cfm>
            <soft_erp>0.2</soft_erp>
            <kp>1e+10</kp>
            <kd>1</kd>
            <min_depth>0.01</min_depth>
          </ode>
        </contact>
      </surface>
    </collision>
    <visual>
      <origin rpy="0 0 0.0" xyz="0 0 0" />
      <geometry>
        
        <mesh filename="https://raw.githubusercontent.com/CM134/urdf-test/main/meshes/wheel.dae" scale="1.4194444444444445 2.5 1.4194444444444445" />
      </geometry>
    </visual>
    <inertial>
      <origin rpy="1.5707963267948966 0 0" xyz="0 0 0" />
      <mass value="125.0" />
      <inertia ixx="3.7166666666666672" ixy="0" ixz="0" iyy="3.7166666666666672" iyz="0" izz="7.225000000000001" />
    </inertial>
  </link>
  <joint name="tractor_right_wheel_joint" type="continuous">
    <parent link="base_link" />
    <child link="tractor_right_wheel" />
    <origin rpy="0 0 0" xyz="-0.3 -0.25 0.39" />
    <limit effort="100" velocity="100.0" />
    <axis xyz="0 1 0" />
  </joint>
  <link name="tractor_left_wheel">
    <collision>
      
      <origin rpy="1.57079633 0 0" xyz="0 0 0" />
      <geometry>
        <cylinder length="0.1" radius="0.34" />
      </geometry>
      <surface>
        <friction>
          <ode>
            <mu>1</mu>
            <mu2>0.25</mu2>
            <slip1>0.00001</slip1>
            <slip2>0.00001</slip2>
          </ode>
        </friction>
        <contact>
          <ode>
            <soft_cfm>0</soft_cfm>
            <soft_erp>0.2</soft_erp>
            <kp>1e+10</kp>
            <kd>1</kd>
            <min_depth>0.01</min_depth>
          </ode>
        </contact>
      </surface>
    </collision>
    <visual>
      <origin rpy="0 0 3.14" xyz="0 0 0" />
      <geometry>
        
        <mesh filename="https://raw.githubusercontent.com/CM134/urdf-test/main/meshes/wheel.dae" scale="1.4194444444444445 2.5 1.4194444444444445" />
      </geometry>
    </visual>
    <inertial>
      <origin rpy="1.5707963267948966 0 0" xyz="0 0 0" />
      <mass value="125.0" />
      <inertia ixx="3.7166666666666672" ixy="0" ixz="0" iyy="3.7166666666666672" iyz="0" izz="7.225000000000001" />
    </inertial>
  </link>
  <joint name="tractor_left_wheel_joint" type="continuous">
    <parent link="base_link" />
    <child link="tractor_left_wheel" />
    <origin rpy="0 0 0" xyz="-0.3 0.25 0.39" />
    <limit effort="100" velocity="100.0" />
    <axis xyz="0 1 0" />
  </joint>
  <link name="tractor_caster_wheel_front">
    <visual>
      <origin rpy="0 0 0" xyz="0 0 0" />
      <geometry>
        <sphere radius="0.15" />
      </geometry>
    </visual>
    <collision>
      <origin rpy="0 0 0" xyz="0 0 0" />
      <geometry>
        <sphere radius="0.15" />
      </geometry>
      <surface>
        <friction>
          <ode>
            <mu>0.0</mu>
            <mu2>0.0</mu2>
          </ode>
        </friction>
        <contact>
          <ode>
            <min_depth>0.01</min_depth>
          </ode>
        </contact>
      </surface>
    </collision>
    <inertial>
      <mass value="0.1" />
      <inertia ixx="0.0009000000000000002" ixy="0.0" ixz="0.0" iyy="0.0009000000000000002" iyz="0.0" izz="0.0009000000000000002" />
    </inertial>
  </link>
  <joint name="tractor_caster_wheel_front" type="fixed">
    <parent link="tractor_chassis" />
    <child link="tractor_caster_wheel_front" />
    <origin rpy="0 0 0" xyz="0.9 0.0 0.15" />
  </joint>
  <link name="tractor_caster_wheel_rear">
    <visual>
      <origin rpy="0 0 0" xyz="0 0 0" />
      <geometry>
        <sphere radius="0.15" />
      </geometry>
    </visual>
    <collision>
      <origin rpy="0 0 0" xyz="0 0 0" />
      <geometry>
        <sphere radius="0.15" />
      </geometry>
      <surface>
        <friction>
          <ode>
            <mu>0.0</mu>
            <mu2>0.0</mu2>
          </ode>
        </friction>
        <contact>
          <ode>
            <min_depth>0.01</min_depth>
          </ode>
        </contact>
      </surface>
    </collision>
    <inertial>
      <mass value="0.1" />
      <inertia ixx="0.0009000000000000002" ixy="0.0" ixz="0.0" iyy="0.0009000000000000002" iyz="0.0" izz="0.0009000000000000002" />
    </inertial>
  </link>
  <joint name="tractor_caster_wheel_rear" type="fixed">
    <parent link="tractor_chassis" />
    <child link="tractor_caster_wheel_rear" />
    <origin rpy="0 0 0" xyz="-0.9 0.0 0.15" />
  </joint>
  <link name="nominal_tractor_camera_mount_front">
    <inertial>
      <mass value="0.0005" />
      <origin rpy=" 0 0 0" xyz="0 0 0" />
      <inertia ixx="0.001" ixy="0" ixz="0" iyy="0.001" iyz="0" izz="0.001" />
    </inertial>
    <collision name="nominal_tractor_camera_mount_front_collision">
      <origin rpy=" 0 0 0" xyz="0 0 0" />
      <geometry>
        <mesh filename="package://sensor_description/models/arkvision_arkcam_mini/meshes/ark_cam_basic_red.dae" scale="0.001 0.001 0.001" />
      </geometry>
    </collision>
    <visual>
      <origin rpy="0 0 0" xyz="0 0 0" />
      <geometry>
        <mesh filename="https://raw.githubusercontent.com/CM134/urdf-test/main/meshes/ark_cam_basic_red.dae" scale="0.001 0.001 0.001" />
      </geometry>
    </visual>
  </link>
  <joint name="nominal_tractor_camera_mount_front_joint" type="fixed">
    <origin rpy="0 0.93 0" xyz="0.910 0 2.050" />
    <parent link="base_link" />
    <child link="nominal_tractor_camera_mount_front" />
  </joint>
  <link name="nominal_tractor_camera_front">
    <inertial>
      <mass value="0.0005" />
      <origin rpy=" 0 0 0" xyz="0 0 0" />
      <inertia ixx="0.001" ixy="0" ixz="0" iyy="0.001" iyz="0" izz="0.001" />
    </inertial>
  </link>
  <joint name="nominal_tractor_camera_front_joint" type="fixed">
    <origin rpy="0 0 0" xyz="0.015 0 0" />
    <parent link="nominal_tractor_camera_mount_front" />
    <child link="nominal_tractor_camera_front" />
  </joint>
  <link name="nominal_tractor_camera_front_optical_frame">
    <inertial>
      <mass value="0.0005" />
      <origin rpy=" 0 0 0" xyz="0 0 0" />
      <inertia ixx="0.001" ixy="0" ixz="0" iyy="0.001" iyz="0" izz="0.001" />
    </inertial>
  </link>
  <joint name="nominal_tractor_camera_front_optical_joint" type="fixed">
    <origin rpy="0 0 0" xyz="0 0 0" />
    <parent link="nominal_tractor_camera_front" />
    <child link="nominal_tractor_camera_front_optical_frame" />
  </joint>
  <link name="tractor_camera_front_optical_frame">
    <inertial>
      <mass value="0.0005" />
      <origin rpy=" 0 0 0" xyz="0 0 0" />
      <inertia ixx="0.001" ixy="0" ixz="0" iyy="0.001" iyz="0" izz="0.001" />
    </inertial>
  </link>
  <joint name="nominal_tractor_camera_front_optical_frame_tractor_camera_front_optical_frame_joint" type="fixed">
    <parent link="nominal_tractor_camera_front_optical_frame" />
    <child link="tractor_camera_front_optical_frame" />
    <origin rpy="0 0 0" xyz="0 0 0" />
  </joint>
  <link name="nominal_tractor_camera_mount_rear">
    <inertial>
      <mass value="0.0005" />
      <origin rpy=" 0 0 0" xyz="0 0 0" />
      <inertia ixx="0.001" ixy="0" ixz="0" iyy="0.001" iyz="0" izz="0.001" />
    </inertial>
    <collision name="nominal_tractor_camera_mount_rear_collision">
      <origin rpy=" 0 0 0" xyz="0 0 0" />
      <geometry>
        <mesh filename="package://sensor_description/models/arkvision_arkcam_mini/meshes/ark_cam_basic_red.dae" scale="0.001 0.001 0.001" />
      </geometry>
    </collision>
    <visual>
      <origin rpy="0 0 0" xyz="0 0 0" />
      <geometry>
        <mesh filename="https://raw.githubusercontent.com/CM134/urdf-test/main/meshes/ark_cam_basic_red.dae" scale="0.001 0.001 0.001" />
      </geometry>
    </visual>
  </link>
  <joint name="nominal_tractor_camera_mount_rear_joint" type="fixed">
    <origin rpy="0 0.58 3.141592653589793" xyz="-0.395 0 2.135" />
    <parent link="base_link" />
    <child link="nominal_tractor_camera_mount_rear" />
  </joint>
  <link name="nominal_tractor_camera_rear">
    <inertial>
      <mass value="0.0005" />
      <origin rpy=" 0 0 0" xyz="0 0 0" />
      <inertia ixx="0.001" ixy="0" ixz="0" iyy="0.001" iyz="0" izz="0.001" />
    </inertial>
  </link>
  <joint name="nominal_tractor_camera_rear_joint" type="fixed">
    <origin rpy="0 0 0" xyz="0.015 0 0" />
    <parent link="nominal_tractor_camera_mount_rear" />
    <child link="nominal_tractor_camera_rear" />
  </joint>
  <link name="nominal_tractor_camera_rear_optical_frame">
    <inertial>
      <mass value="0.0005" />
      <origin rpy=" 0 0 0" xyz="0 0 0" />
      <inertia ixx="0.001" ixy="0" ixz="0" iyy="0.001" iyz="0" izz="0.001" />
    </inertial>
  </link>
  <joint name="nominal_tractor_camera_rear_optical_joint" type="fixed">
    <origin rpy="0 0 0" xyz="0 0 0" />
    <parent link="nominal_tractor_camera_rear" />
    <child link="nominal_tractor_camera_rear_optical_frame" />
  </joint>
  <link name="tractor_camera_rear_optical_frame">
    <inertial>
      <mass value="0.0005" />
      <origin rpy=" 0 0 0" xyz="0 0 0" />
      <inertia ixx="0.001" ixy="0" ixz="0" iyy="0.001" iyz="0" izz="0.001" />
    </inertial>
  </link>
  <joint name="nominal_tractor_camera_rear_optical_frame_tractor_camera_rear_optical_frame_joint" type="fixed">
    <parent link="nominal_tractor_camera_rear_optical_frame" />
    <child link="tractor_camera_rear_optical_frame" />
    <origin rpy="0 0 0" xyz="0 0 0" />
  </joint>
  
  <link name="nominal_tractor_lidar_front">
    <inertial>
      <mass value="0.00002" />
      <origin xyz="0 0 0.03585" />
      <inertia ixx="2.1880950000000003e-08" ixy="0" ixz="0" iyy="2.1880950000000003e-08" iyz="0" izz="2.66256e-08" />
    </inertial>
    <visual>
      <origin rpy="1.5708 0 -1.5708" xyz="0 0 0" />
      <geometry>
        <mesh filename="https://raw.githubusercontent.com/CM134/urdf-test/main/meshes/OS0.dae" />
      </geometry>
    </visual>
    <collision>
      <origin rpy="0 0 0" xyz="0 0 0.03585" />
      <geometry>
        <cylinder length="0.0717" radius="0.0516" />
      </geometry>
    </collision>
  </link>
  <joint name="nominal_tractor_lidar_front_joint" type="fixed">
    <origin rpy="0 0 3.141592653589793" xyz="1.025 0 1.375" />
    <parent link="base_link" />
    <child link="nominal_tractor_lidar_front" />
  </joint>
  <link name="tractor_lidar_front/laser" />
  <joint name="tractor_lidar_front_laser" type="fixed">
    <origin rpy="0.0 0.0 3.14" xyz="0 0 36.180e-3" />
    <parent link="tractor_lidar_front" />
    <child link="tractor_lidar_front/laser" />
  </joint>
  <link name="tractor_lidar_front/imu" />
  <joint name="tractor_lidar_front_imu" type="fixed">
    <origin rpy="0.0 0.0 0.0" xyz="6.253e-3 -11.775e-3 7.645e-3" />
    <parent link="tractor_lidar_front" />
    <child link="tractor_lidar_front/imu" />
  </joint>
  <link name="tractor_lidar_front">
    <inertial>
      <mass value="0.0005" />
      <origin rpy=" 0 0 0" xyz="0 0 0" />
      <inertia ixx="0.001" ixy="0" ixz="0" iyy="0.001" iyz="0" izz="0.001" />
    </inertial>
  </link>
  <joint name="nominal_tractor_lidar_front_tractor_lidar_front_joint" type="fixed">
    <parent link="nominal_tractor_lidar_front" />
    <child link="tractor_lidar_front" />
    <origin rpy="0 0 0" xyz="0 0 0" />
  </joint>
  
  <link name="nominal_tractor_radar_front_left">
    <inertial>
      <mass value="0.0005" />
      <origin rpy=" 0 0 0" xyz="0 0 0" />
      <inertia ixx="0.001" ixy="0" ixz="0" iyy="0.001" iyz="0" izz="0.001" />
    </inertial>
    <collision name="nominal_tractor_radar_front_left_collision">
      <origin rpy=" 0 0 0" xyz="0 0 0" />
      <geometry>
        <box size="0.02 0.1 0.1" />
      </geometry>
    </collision>
    <visual name="nominal_tractor_radar_front_left_visual">
      <origin rpy=" 0 1.57079 -1.57079" xyz="0 -0.002 0" />
      <geometry>
        
        <mesh filename="https://raw.githubusercontent.com/CM134/urdf-test/main/meshes/smartmicro_type153.dae" scale="1.0 1.0 1.0" />
      </geometry>
    </visual>
  </link>
  <joint name="nominal_tractor_radar_front_left_joint" type="fixed">
    <origin rpy="0 0.0 0.87" xyz="0.87 0.15 1.11" />
    <parent link="base_link" />
    <child link="nominal_tractor_radar_front_left" />
  </joint>
  <link name="nominal_tractor_radar_front_left_optical_frame">
    <inertial>
      <mass value="0.0005" />
      <origin rpy=" 0 0 0" xyz="0 0 0" />
      <inertia ixx="0.001" ixy="0" ixz="0" iyy="0.001" iyz="0" izz="0.001" />
    </inertial>
  </link>
  <joint name="nominal_tractor_radar_front_left_optical_joint" type="fixed">
    <origin rpy="-1.57 0 -1.57" xyz="0 0 0" />
    <parent link="nominal_tractor_radar_front_left" />
    <child link="nominal_tractor_radar_front_left_optical_frame" />
  </joint>
  <link name="tractor_radar_front_left">
    <inertial>
      <mass value="0.0005" />
      <origin rpy=" 0 0 0" xyz="0 0 0" />
      <inertia ixx="0.001" ixy="0" ixz="0" iyy="0.001" iyz="0" izz="0.001" />
    </inertial>
  </link>
  <joint name="nominal_tractor_radar_front_left_tractor_radar_front_left_joint" type="fixed">
    <parent link="nominal_tractor_radar_front_left" />
    <child link="tractor_radar_front_left" />
    <origin rpy="0 0 0" xyz="0 0 0" />
  </joint>
  
  <link name="nominal_tractor_radar_front_right">
    <inertial>
      <mass value="0.0005" />
      <origin rpy=" 0 0 0" xyz="0 0 0" />
      <inertia ixx="0.001" ixy="0" ixz="0" iyy="0.001" iyz="0" izz="0.001" />
    </inertial>
    <collision name="nominal_tractor_radar_front_right_collision">
      <origin rpy=" 0 0 0" xyz="0 0 0" />
      <geometry>
        <box size="0.02 0.1 0.1" />
      </geometry>
    </collision>
    <visual name="nominal_tractor_radar_front_right_visual">
      <origin rpy=" 0 1.57079 -1.57079" xyz="0 -0.002 0" />
      <geometry>
        
        <mesh filename="https://raw.githubusercontent.com/CM134/urdf-test/main/meshes/smartmicro_type153.dae" scale="1.0 1.0 1.0" />
      </geometry>
    </visual>
  </link>
  <joint name="nominal_tractor_radar_front_right_joint" type="fixed">
    <origin rpy="3.141592653589793 0.0 -0.89" xyz="0.87 -0.15 1.11" />
    <parent link="base_link" />
    <child link="nominal_tractor_radar_front_right" />
  </joint>
  <link name="nominal_tractor_radar_front_right_optical_frame">
    <inertial>
      <mass value="0.0005" />
      <origin rpy=" 0 0 0" xyz="0 0 0" />
      <inertia ixx="0.001" ixy="0" ixz="0" iyy="0.001" iyz="0" izz="0.001" />
    </inertial>
  </link>
  <joint name="nominal_tractor_radar_front_right_optical_joint" type="fixed">
    <origin rpy="-1.57 0 -1.57" xyz="0 0 0" />
    <parent link="nominal_tractor_radar_front_right" />
    <child link="nominal_tractor_radar_front_right_optical_frame" />
  </joint>
  <link name="tractor_radar_front_right">
    <inertial>
      <mass value="0.0005" />
      <origin rpy=" 0 0 0" xyz="0 0 0" />
      <inertia ixx="0.001" ixy="0" ixz="0" iyy="0.001" iyz="0" izz="0.001" />
    </inertial>
  </link>
  <joint name="nominal_tractor_radar_front_right_tractor_radar_front_right_joint" type="fixed">
    <parent link="nominal_tractor_radar_front_right" />
    <child link="tractor_radar_front_right" />
    <origin rpy="0 0 0" xyz="0 0 0" />
  </joint>
  <link name="tractor_radar_saferadar">
    <inertial>
      <mass value="0.0005" />
      <origin rpy=" 0 0 0" xyz="0 0 0" />
      <inertia ixx="0.001" ixy="0" ixz="0" iyy="0.001" iyz="0" izz="0.001" />
    </inertial>
  </link>
  <joint name="base_link_tractor_radar_saferadar_joint" type="fixed">
    <parent link="base_link" />
    <child link="tractor_radar_saferadar" />
    <origin rpy="0 0 0" xyz="0.98 0 1.175" />
  </joint>
  <link name="tractor_gnss_front_link">
    <inertial>
      <mass value="0.0005" />
      <origin rpy=" 0 0 0" xyz="0 0 0" />
      <inertia ixx="0.001" ixy="0" ixz="0" iyy="0.001" iyz="0" izz="0.001" />
    </inertial>
    <collision>
      <origin rpy=" 0 0 0" xyz="0 0 0" />
      <geometry>
        <cylinder length="0.05" radius="0.1" />
      </geometry>
    </collision>
    <visual>
      <origin rpy=" 0 0 0" xyz="0 0 0" />
      <geometry>
        <mesh filename="https://raw.githubusercontent.com/CM134/urdf-test/main/meshes/generic_gnss.dae" />
      </geometry>
    </visual>
  </link>
  <joint name="tractor_gnss_front_joint" type="fixed">
    <parent link="base_link" />
    <child link="tractor_gnss_front_link" />
    <origin rpy="0 0 0" xyz="0.985 0.0 2.18" />
  </joint>
  <link name="tractor_gnss_rear_link">
    <inertial>
      <mass value="0.0005" />
      <origin rpy=" 0 0 0" xyz="0 0 0" />
      <inertia ixx="0.001" ixy="0" ixz="0" iyy="0.001" iyz="0" izz="0.001" />
    </inertial>
    <collision>
      <origin rpy=" 0 0 0" xyz="0 0 0" />
      <geometry>
        <cylinder length="0.05" radius="0.1" />
      </geometry>
    </collision>
    <visual>
      <origin rpy=" 0 0 0" xyz="0 0 0" />
      <geometry>
        <mesh filename="https://raw.githubusercontent.com/CM134/urdf-test/main/meshes/generic_gnss.dae" />
      </geometry>
    </visual>
  </link>
  <joint name="tractor_gnss_rear_joint" type="fixed">
    <parent link="base_link" />
    <child link="tractor_gnss_rear_link" />
    <origin rpy="0 0 0" xyz="-0.2699999999999999 -0.0 2.18" />
  </joint>
  <link name="tractor_imu_center">
    <inertial>
      <mass value="0.0005" />
      <origin rpy=" 0 0 0" xyz="0 0 0" />
      <inertia ixx="0.001" ixy="0" ixz="0" iyy="0.001" iyz="0" izz="0.001" />
    </inertial>
    <collision>
      <origin rpy=" 0 0 0" xyz="0 0 0" />
      <geometry>
        <box size="0.05 0.05 0.05" />
      </geometry>
    </collision>
    <visual>
      <origin rpy=" 0 0 0" xyz="0 0 0" />
      <geometry>
        <box size="0.05 0.05 0.05" />
      </geometry>
    </visual>
  </link>
  <joint name="tractor_imu_center_joint" type="fixed">
    <origin rpy="0 0 0" xyz="0 0 0.25" />
    <parent link="tractor_chassis" />
    <child link="tractor_imu_center" />
    <origin rpy="0 0 0" xyz="0 0 0.25" />
  </joint>
</robot>
